<?xml version="1.0"?>
<robot xmlns:xacro="http://www.ros.org/wiki/xacro" >

<xacro:include filename="inertial_macros.xacro" />
    <material name="white">
        <color rgba="1 1 1 1"/>
    </material>

    <material name="orange">
        <color rgba="1 0.3 0.1 1"/>
    </material>

    <material name="blue">
        <color rgba="0.2 0.2 1 1"/>
    </material>

    <material name="black">
        <color rgba="0 0 0 1"/>
    </material>

    <material name="red">
        <color rgba="1 0 0 1"/>
    </material>
    
    <!--  BASE LINK  -->

    <link name="base_link">

    </link>


    <!--  CHASSIS LINK  -->

    <joint name="chassis_joint" type="fixed">
        <parent link="base_link"/>
        <child link="chassis"/>
        <origin xyz="-0.26 0 0"/>
    </joint>

    <link name="chassis">
        <visual>
            <origin xyz="0.41 0 0.225" rpy="0 0 0"/>
            <geometry>
                <box size="0.82 0.49 0.45"/>
            </geometry>
            <material name="red"/>
        </visual>

        <collision>
            <origin xyz="0.41 0 0.225" rpy="0 0 0"/>
            <geometry>
                <box size="0.82 0.49 0.45"/>
            </geometry>
        </collision>

        <xacro:inertial_box mass="35" x="0.82" y="0.49" z="0.45">
            <origin xyz="0.41 0 0.225" rpy="0 0 0"/>
        </xacro:inertial_box>

    </link>

    <gazebo reference="chassis">
        <material>Gazebo/Red</material>
    </gazebo>

    <!--  LEFT WHEEL LINK  -->

    <joint name="left_wheel_joint" type="continuous">
        <parent link="base_link"/>
        <child link="left_wheel"/>
        <origin xyz="0 0.285 0" rpy="-${pi/2} 0 0"/>
        <axis xyz="0 0 2"/>
    </joint>

    <link name="left_wheel">
        <visual>
            <geometry>
                <cylinder length="0.08" radius="0.17" />/>
            </geometry>
            <material name="blue"/>
        </visual>

        <collision>
            <geometry>
                <sphere radius="0.17" />/>
            </geometry>
        </collision>

        <xacro:inertial_cylinder mass="1" length="0.08" radius="0.17">
            <origin xyz="0 0 0" rpy="0 0 0"/>
        </xacro:inertial_cylinder>

    </link>

    <gazebo reference="left_wheel">
        <material>Gazebo/Grey</material>
    </gazebo>

    <!-- RIGHT WHEEL -->

    <joint name="right_wheel_joint" type="continuous">
        <parent link="base_link"/>
        <child link="right_wheel"/>
        <origin xyz="0 -0.285 0" rpy="${pi/2} 0 0"/>
        <axis xyz="0 0 -2"/>
    </joint>

    <link name="right_wheel">
        <visual>
            <geometry>
                <cylinder length="0.08" radius="0.17" />/>
            </geometry>
            <material name="blue"/>
        </visual>

        <collision>
            <geometry>
                <sphere radius="0.17" />/>
            </geometry>
        </collision>

        <xacro:inertial_cylinder mass="1" length="0.08" radius="0.17">
            <origin xyz="0 0 0" rpy="0 0 0"/>
        </xacro:inertial_cylinder>

    </link>

    <gazebo reference="right_wheel">
        <material>Gazebo/Grey</material>
    </gazebo>


  
    <!--  LEFT FRONT WHEEL LINK  -->

    <joint name="left_front_wheel_joint" type="fixed">
        <parent link="base_link"/>
        <child link="left_front_wheel"/>
        <origin xyz="0.5 0.285 -0.04" rpy="-${pi/2} 0 0"/>
        <axis xyz="0 0 2"/>
    </joint>

    <link name="left_front_wheel">
        <visual>
            <geometry>
                <cylinder length="0.08" radius="0.13" />/>
            </geometry>
            <material name="blue"/>
        </visual>

        <collision>
            <geometry>
                <sphere radius="0.13" />
            </geometry>
        </collision>

        <xacro:inertial_cylinder mass="1" length="0.08" radius="0.13">
            <origin xyz="0 0 0" rpy="0 0 0"/>
        </xacro:inertial_cylinder>

    </link>

    <gazebo reference="left_front_wheel">
        <material>Gazebo/Grey</material>
        <mu1 value="0.001"/>
        <mu2 value="0.001"/>
    </gazebo>
    

    <!--  RIGHT FRONT WHEEL LINK  -->

    <joint name="right_front_wheel_joint" type="fixed">
        <parent link="base_link"/>
        <child link="right_front_wheel"/>
        <origin xyz="0.5 -0.285 -0.04" rpy="${pi/2} 0 0"/>
        <axis xyz="0 0 -2"/>
    </joint>

    <link name="right_front_wheel">
        <visual>
            <geometry>
                <cylinder length="0.08" radius="0.13" />/>
            </geometry>
            <material name="blue"/>
        </visual>

        <collision>
            <geometry>
                <sphere radius="0.13" />
            </geometry>
        </collision>

        <xacro:inertial_cylinder mass="1" length="0.08" radius="0.13">
            <origin xyz="0 0 0" rpy="0 0 0"/>
        </xacro:inertial_cylinder>

    </link>

    <gazebo reference="right_front_wheel">
        <material>Gazebo/Grey</material>
        <mu1 value="0.001"/>
        <mu2 value="0.001"/>
    </gazebo>


</robot>